#VRML_SIM R2025a utf8
EXTERNPROTO "https://raw.githubusercontent.com/cyberbotics/webots/R2025a/projects/objects/backgrounds/protos/TexturedBackground.proto"
EXTERNPROTO "https://raw.githubusercontent.com/cyberbotics/webots/R2025a/projects/objects/backgrounds/protos/TexturedBackgroundLight.proto"
EXTERNPROTO "https://raw.githubusercontent.com/cyberbotics/webots/R2025a/projects/objects/floors/protos/RectangleArena.proto"
EXTERNPROTO "https://raw.githubusercontent.com/cyberbotics/webots/R2025a/projects/robots/robotis/turtlebot/protos/TurtleBot3Burger.proto"

WorldInfo { }
TexturedBackground { }
TexturedBackgroundLight { }
RectangleArena { }

TurtleBot3Burger {
  controller "main_controller"
  extensionSlot [
    HingeJoint {
      jointParameters HingeJointParameters {
        axis 0 0 1
        anchor 0 0 0.18
      }
      device [
        RotationalMotor {
          name "camera_motor"
        }
      ]
      endPoint Solid {
        name "camera_mount"
        translation 0 0 0.18
        children [
          Camera {
            name "rgb_camera"
            width 640
            height 480
            fieldOfView 1.047
            near 0.01
            far 20.0
          }
        ]
      }
    }
  ]
}
