#VRML_SIM R2025a utf8

EXTERNPROTO "https://raw.githubusercontent.com/cyberbotics/webots/R2025a/projects/objects/backgrounds/protos/TexturedBackground.proto"
EXTERNPROTO "https://raw.githubusercontent.com/cyberbotics/webots/R2025a/projects/objects/backgrounds/protos/TexturedBackgroundLight.proto"
EXTERNPROTO "https://raw.githubusercontent.com/cyberbotics/webots/R2025a/projects/robots/robotis/turtlebot/protos/TurtleBot3Burger.proto"
EXTERNPROTO "https://raw.githubusercontent.com/cyberbotics/webots/R2025a/projects/objects/solids/protos/SolidBox.proto"
EXTERNPROTO "https://raw.githubusercontent.com/cyberbotics/webots/R2025a/projects/devices/robotis/protos/RobotisLds01.proto"

WorldInfo {
}
Viewpoint {
  orientation -0.564862634547823 0.4908425908838637 0.6633277885526192 2.095818902119859
  position 0.64242116770508 -2.844847814165946 16.138066165629898
}
TexturedBackground {
}
TexturedBackgroundLight {
}

# FLOOR 3× (was 7, now 4.2)
DEF FLOOR Solid {
  children [
    DEF FLOOR_SHAPE Shape {
      appearance PBRAppearance {
        baseColor 0.42 0.73 0.44
        roughness 1
        metalness 0
      }
      geometry Plane {
        size 4.2 4.2
      }
    }
  ]
  name "ground"
  boundingObject USE FLOOR_SHAPE
  locked TRUE
}

# BORDER 3× (was 9, now 5.4)
DEF FLOOR_BORDER Solid {
  translation 0 0 -0.001
  children [
    DEF FLOOR_BORDER_SHAPE Shape {
      appearance PBRAppearance {
        baseColor 0.21 0.22 0.24
        roughness 1
        metalness 0
      }
      geometry Plane {
        size 5.4 5.4
      }
    }
  ]
}

# WALLS 3×
DEF WALL Solid {
  children [
    Shape {
      appearance DEF WALL_APPEARANCE PBRAppearance {
        baseColor 0.42 0.73 0.44
        roughness 1
        metalness 0
      }
      geometry DEF WALL_GEOMETRY IndexedFaceSet {
        coord Coordinate {
          point [
            -2.7 -2.7 0
            2.7 -2.7 0
            2.7 2.7 0
            -2.7 2.7 0

            -2.7 2.67 0
            2.67 2.67 0
            2.67 -2.67 0
            -2.67 -2.67 0
            -2.67 2.67 0
            -2.7 2.67 0
            -2.7 -2.7 0

            -2.7 -2.7 0.3
            2.7 -2.7 0.3
            2.7 2.7 0.3
            -2.7 2.7 0.3

            -2.7 2.67 0.3
            2.67 2.67 0.3
            2.67 -2.67 0.3
            -2.67 -2.67 0.3
            -2.67 2.67 0.3
            -2.7 2.67 0.3
            -2.7 -2.7 0.3
          ]
        }

        coordIndex [
          10,9,8,7,6,5,4,3,2,1,0,-1,
          11,12,13,14,15,16,17,18,19,20,21,-1,
          0,1,12,11,-1,
          1,2,13,12,-1,
          2,3,14,13,-1,
          3,4,15,14,-1,
          4,5,16,15,-1,
          5,6,17,16,-1,
          6,7,18,17,-1,
          7,8,19,18,-1,
          8,9,20,19,-1,
          9,10,21,20,-1
        ]
      }
    }
  ]

  name "wall"

  boundingObject Group {
    children [

      # bottom wall (was 4.45 → now 2.67)
      Pose {
        translation 0 -2.67 0.15
        children [
          DEF WALL_SHAPE Shape {
            appearance USE WALL_APPEARANCE
            geometry Box {
              size 5.4 0.01 0.3
            }
          }
        ]
      }

      Pose {
        translation 0 2.67 0.15
        children [ USE WALL_SHAPE ]
      }

      Pose {
        translation -2.67 0 0.15
        rotation 0 0 1 1.57
        children [ USE WALL_SHAPE ]
      }

      Pose {
        translation 2.67 0 0.15
        rotation 0 0 1 1.57
        children [ USE WALL_SHAPE ]
      }
    ]
  }

  locked TRUE
}

# BOXES (unchanged)
SolidBox {
  translation 0.5 1 0.1
  rotation 0 0 1 1.5708
  name "box(1)"
  size 0.2 0.2 0.2
  appearance PBRAppearance {
    baseColor 1 0 0
    roughness 1
    metalness 0
  }
}

SolidBox {
  translation -2.9 -1.29001 0.1
  rotation 0 0 1 1.5708
  name "box(2)"
  size 0.2 0.2 0.2
  appearance PBRAppearance {
    baseColor 1 0 0
    roughness 1
    metalness 0
  }
}

# ROBOT (unchanged)
TurtleBot3Burger {
  translation 0 0 0
  rotation 0 0 1 0
  controller "main_controller"
  extensionSlot [
    RobotisLds01 {
    }
    Display {
      width 150
      height 150
    }
    InertialUnit {
    }
    HingeJoint {
      jointParameters HingeJointParameters {
        position 44.17023999999726
        axis 0 0 1
        anchor 0 0 0.18
      }
      device [
        RotationalMotor {
          name "camera_motor"
        }
        PositionSensor {
          name "camera_motor_sensor"
        }
      ]
      endPoint Solid {
        translation 0 0 0.18
        rotation -0.014472692250146819 0.9811691893084558 0.1926072769415016 0.1528677378923613
        children [
          Camera {
            name "rgb_camera"
            fieldOfView 1.047
            width 640
            height 480
            far 20
          }
        ]
        name "camera_mount"
      }
    }
  ]
}
