#VRML_SIM R2025a utf8

EXTERNPROTO "https://raw.githubusercontent.com/cyberbotics/webots/R2025a/projects/objects/backgrounds/protos/TexturedBackground.proto"
EXTERNPROTO "https://raw.githubusercontent.com/cyberbotics/webots/R2025a/projects/objects/backgrounds/protos/TexturedBackgroundLight.proto"
EXTERNPROTO "https://raw.githubusercontent.com/cyberbotics/webots/R2025a/projects/robots/robotis/turtlebot/protos/TurtleBot3Burger.proto"
EXTERNPROTO "https://raw.githubusercontent.com/cyberbotics/webots/R2025a/projects/objects/solids/protos/SolidBox.proto"
EXTERNPROTO "https://raw.githubusercontent.com/cyberbotics/webots/R2025a/projects/devices/robotis/protos/RobotisLds01.proto"

WorldInfo {
}
Viewpoint {
  orientation 0.5454884860485828 0.3711454390691384 -0.7514608270872152 2.196314450312167
  position -1.7481213057974616 6.301871936159155 15.697246528986282
}
TexturedBackground {
}
TexturedBackgroundLight {
}
DEF FLOOR Solid {
  children [
    DEF FLOOR_SHAPE Shape {
      appearance PBRAppearance {
        baseColor 0.42 0.73 0.44
        roughness 1
        metalness 0
      }
      geometry Plane {
        size 4.2 4.2
      }
    }
  ]
  name "ground"
  boundingObject USE FLOOR_SHAPE
  locked TRUE
}
SolidBox {
  translation 0.84 -1.19 0.1
  rotation 0 0 -1 -5.307179586466759e-06
  name "box(6)"
  size 0.1 0.4 0.2
  appearance PBRAppearance {
    roughness 1
    metalness 0
  }
}
DEF FLOOR_BORDER Solid {
  translation 0 0 -0.001
  children [
    DEF FLOOR_BORDER_SHAPE Shape {
      appearance PBRAppearance {
        baseColor 0.21 0.22 0.24
        roughness 1
        metalness 0
      }
      geometry Plane {
        size 5.4 5.4
      }
    }
  ]
}
DEF WALL Solid {
  children [
    Shape {
      appearance DEF WALL_APPEARANCE PBRAppearance {
        baseColor 0.42 0.73 0.44
        roughness 1
        metalness 0
      }
      geometry DEF WALL_GEOMETRY IndexedFaceSet {
        coord Coordinate {
          point [
            -2.7 -2.7 0
            2.7 -2.7 0
            2.7 2.7 0
            -2.7 2.7 0
            -2.7 2.67 0
            2.67 2.67 0
            2.67 -2.67 0
            -2.67 -2.67 0
            -2.67 2.67 0
            -2.7 2.67 0
            -2.7 -2.7 0
            -2.7 -2.7 0.3
            2.7 -2.7 0.3
            2.7 2.7 0.3
            -2.7 2.7 0.3
            -2.7 2.67 0.3
            2.67 2.67 0.3
            2.67 -2.67 0.3
            -2.67 -2.67 0.3
            -2.67 2.67 0.3
            -2.7 2.67 0.3
            -2.7 -2.7 0.3
          ]
        }
        coordIndex [
          10, 9, 8, 7, 6, 5, 4, 3, 2, 1, 0, -1, 11, 12, 13, 14, 15, 16, 17, 18, 19, 20, 21, -1, 0, 1, 12, 11, -1, 1, 2, 13, 12, -1, 2, 3, 14, 13, -1, 3, 4, 15, 14, -1, 4, 5, 16, 15, -1, 5, 6, 17, 16, -1, 6, 7, 18, 17, -1, 7, 8, 19, 18, -1, 8, 9, 20, 19, -1, 9, 10, 21, 20, -1
        ]
      }
    }
  ]
  name "wall"
  boundingObject Group {
    children [
      Pose {
        translation 0 -2.67 0.15
        children [
          DEF WALL_SHAPE Shape {
            appearance USE WALL_APPEARANCE
            geometry Box {
              size 5.4 0.01 0.3
            }
          }
        ]
      }
      Pose {
        translation 0 2.67 0.15
        children [
          USE WALL_SHAPE
        ]
      }
      Pose {
        translation -2.67 0 0.15
        rotation 0 0 1 1.57
        children [
          USE WALL_SHAPE
        ]
      }
      Pose {
        translation 2.67 0 0.15
        rotation 0 0 1 1.57
        children [
          USE WALL_SHAPE
        ]
      }
    ]
  }
  locked TRUE
}
SolidBox {
  translation -0.899999 1.3 0.1
  rotation 0 0 1 1.5708
  name "box(1)"
  size 0.2 0.2 0.2
  appearance PBRAppearance {
    baseColor 1 0 0
    roughness 1
    metalness 0
  }
}
SolidBox {
  translation -0.089996 -1.6 0.1
  rotation 0 0 1 1.5708
  name "box(2)"
  size 0.2 0.2 0.2
  appearance PBRAppearance {
    baseColor 1 0 0
    roughness 1
    metalness 0
  }
}
SolidBox {
  translation -1.08 -0.67 0.1
  rotation 0 0 1 1.5708
  name "box(4)"
  size 0.1 0.4 0.2
  appearance PBRAppearance {
    roughness 1
    metalness 0
  }
}
SolidBox {
  translation -1.90032 1.19785 0.24
  rotation 0 0 -1 -1.0472053071795866
  name "box(5)"
  size 0.1 0.8 0.2
  appearance PBRAppearance {
    roughness 1
    metalness 0
  }
}
SolidBox {
  translation 1.84 1.05 0.1
  rotation 0 0 1 1.5708
  name "box(7)"
  size 0.1 0.8 0.2
  appearance PBRAppearance {
    roughness 1
    metalness 0
  }
}
SolidBox {
  translation 1.1 -0.190001 0.1
  rotation 0 0 1 1.5708
  name "box(3)"
  size 0.2 0.2 0.2
  appearance PBRAppearance {
    baseColor 1 0 0
    roughness 1
    metalness 0
  }
}
SolidBox {
  translation -1.89 -0.190002 0.1
  rotation 0 0 1 1.5708
  name "box(8)"
  size 0.2 0.2 0.2
  appearance PBRAppearance {
    baseColor 1 0 0
    roughness 1
    metalness 0
  }
}
TurtleBot3Burger {
  translation 0 0 0
  rotation 0 1 0 0
  controller "main_controller"
  extensionSlot [
    RobotisLds01 {
    }
    Display {
      width 150
      height 150
    }
    InertialUnit {
    }
    HingeJoint {
      jointParameters HingeJointParameters {
        axis 0 0 1
        anchor 0 0 0.18
      }
      device [
        RotationalMotor {
          name "camera_motor"
        }
        PositionSensor {
          name "camera_motor_sensor"
        }
      ]
      endPoint Solid {
        translation 0 0 0.18
        rotation 0 1 0 0.15 # 15 degree radian pitch downwards
        children [
          Camera {
            name "rgb_camera"
            fieldOfView 1.047
            width 640
            height 480
            far 20
          }
        ]
        name "camera_mount"
      }
    }
  ]
}
