#VRML_SIM R2025a utf8

EXTERNPROTO "https://raw.githubusercontent.com/cyberbotics/webots/R2025a/projects/objects/backgrounds/protos/TexturedBackground.proto"
EXTERNPROTO "https://raw.githubusercontent.com/cyberbotics/webots/R2025a/projects/objects/backgrounds/protos/TexturedBackgroundLight.proto"
EXTERNPROTO "https://raw.githubusercontent.com/cyberbotics/webots/R2025a/projects/robots/robotis/turtlebot/protos/TurtleBot3Burger.proto"
EXTERNPROTO "https://raw.githubusercontent.com/cyberbotics/webots/R2025a/projects/objects/solids/protos/SolidBox.proto"
EXTERNPROTO "https://raw.githubusercontent.com/cyberbotics/webots/R2025a/projects/devices/robotis/protos/RobotisLds01.proto"

WorldInfo {
}
Viewpoint {
  orientation -0.7317263793309248 -0.09164932699370049 0.6754086960151292 3.310385625092375
  position 1.4500751111978032 -0.8341770649482354 12.875784736950827
}
TexturedBackground {
}
TexturedBackgroundLight {
}
DEF FLOOR Solid {
  children [
    DEF FLOOR_SHAPE Shape {
      appearance PBRAppearance {
        baseColor 0.42 0.73 0.44
        roughness 1
        metalness 0
      }
      geometry Plane {
        size 4.2 4.2
      }
    }
  ]
  name "ground"
  boundingObject USE FLOOR_SHAPE
  locked TRUE
}
DEF FLOOR_BORDER Solid {
  translation 0 0 -0.001
  children [
    DEF FLOOR_BORDER_SHAPE Shape {
      appearance PBRAppearance {
        baseColor 0.21 0.22 0.24
        roughness 1
        metalness 0
      }
      geometry Plane {
        size 5.4 5.4
      }
    }
  ]
}
DEF WALL Solid {
  children [
    Shape {
      appearance DEF WALL_APPEARANCE PBRAppearance {
        baseColor 0.42 0.73 0.44
        roughness 1
        metalness 0
      }
      geometry DEF WALL_GEOMETRY IndexedFaceSet {
        coord Coordinate {
          point [
            -2.7 -2.7 0
            2.7 -2.7 0
            2.7 2.7 0
            -2.7 2.7 0
            -2.7 2.67 0
            2.67 2.67 0
            2.67 -2.67 0
            -2.67 -2.67 0
            -2.67 2.67 0
            -2.7 2.67 0
            -2.7 -2.7 0
            -2.7 -2.7 0.3
            2.7 -2.7 0.3
            2.7 2.7 0.3
            -2.7 2.7 0.3
            -2.7 2.67 0.3
            2.67 2.67 0.3
            2.67 -2.67 0.3
            -2.67 -2.67 0.3
            -2.67 2.67 0.3
            -2.7 2.67 0.3
            -2.7 -2.7 0.3
          ]
        }
        coordIndex [
          10, 9, 8, 7, 6, 5, 4, 3, 2, 1, 0, -1, 11, 12, 13, 14, 15, 16, 17, 18, 19, 20, 21, -1, 0, 1, 12, 11, -1, 1, 2, 13, 12, -1, 2, 3, 14, 13, -1, 3, 4, 15, 14, -1, 4, 5, 16, 15, -1, 5, 6, 17, 16, -1, 6, 7, 18, 17, -1, 7, 8, 19, 18, -1, 8, 9, 20, 19, -1, 9, 10, 21, 20, -1
        ]
      }
    }
  ]
  name "wall"
  boundingObject Group {
    children [
      Pose {
        translation 0 -2.67 0.15
        children [
          DEF WALL_SHAPE Shape {
            appearance USE WALL_APPEARANCE
            geometry Box {
              size 5.4 0.01 0.3
            }
          }
        ]
      }
      Pose {
        translation 0 2.67 0.15
        children [
          USE WALL_SHAPE
        ]
      }
      Pose {
        translation -2.67 0 0.15
        rotation 0 0 1 1.57
        children [
          USE WALL_SHAPE
        ]
      }
      Pose {
        translation 2.67 0 0.15
        rotation 0 0 1 1.57
        children [
          USE WALL_SHAPE
        ]
      }
    ]
  }
  locked TRUE
}
SolidBox {
  translation 0.500001 1.3 0.1
  rotation 0 0 1 1.5708
  name "box(1)"
  size 0.2 0.2 0.2
  appearance PBRAppearance {
    baseColor 1 0 0
    roughness 1
    metalness 0
  }
}
SolidBox {
  translation 1.37 0.01 0.1
  rotation 0 0 1 1.5708
  name "box(3)"
  size 0.2 0.2 0.2
  appearance PBRAppearance {
    baseColor 1 0 0
    roughness 1
    metalness 0
  }
}
TurtleBot3Burger {
  hidden position_0_1 -1.781631865684982e-12
  hidden position_0_2 3.239648112840256e-12
  hidden position_0_3 1.0374314032867513e-06
  hidden position2_0_3 0.00021830908414074662
  hidden position3_0_3 -3.2743330793857073e-07
  hidden linearVelocity_0 -1.250553440062249e-16 -3.1792922642307743e-16 1.781582993746985e-16
  hidden angularVelocity_0 9.762417191440456e-16 -3.1317817705366647e-15 -1.5810521627585126e-16
  hidden rotation_12 0 0.9999999999999999 0 5.077626172073862
  hidden linearVelocity_12 -1.1797565980796852e-16 -2.8102127700129584e-16 5.609754253984995e-16
  hidden angularVelocity_12 -7.478582709062866e-22 -2.9921768388178515e-15 -9.608968068534629e-17
  hidden rotation_13 -0.8084144965753667 3.616432125961106e-07 -0.5886136268611744 3.1415880565521914
  hidden linearVelocity_13 -9.640916729700354e-17 -3.2993499180308996e-16 -4.3631131624555037e-16
  hidden angularVelocity_13 -5.790731749032955e-21 -2.8828082500570444e-15 -9.278883280159692e-17
  hidden rotation_14 0.12319967329605011 -0.23361894483938045 0.9644915910011249 0.9078548354209718
  hidden linearVelocity_14 -1.5241394340848234e-16 -2.7227561295235726e-16 5.047266950564663e-14
  hidden angularVelocity_14 6.806890341417725e-14 -3.803656922760127e-14 -1.653164103111248e-27
  translation 4.940035602807313e-10 -5.202329480017646e-10 -0.0002477392058692768
  rotation -0.002112981064649265 -0.9999977676417207 4.753493435926266e-06 0.00464194679478861
  controller "main_controller"
  extensionSlot [
    RobotisLds01 {
    }
    Display {
      width 150
      height 150
    }
    InertialUnit {
    }
    HingeJoint {
      jointParameters HingeJointParameters {
        position 68.36671999999655
        axis 0 0 1
        anchor 0 0 0.18
      }
      device [
        RotationalMotor {
          name "camera_motor"
        }
        PositionSensor {
          name "camera_motor_sensor"
        }
      ]
      endPoint Solid {
        translation 0 0 0.18
        rotation 0.07405906615101648 0.15199955772918833 -0.9856020440172446 0.9182343884391124
        children [
          Camera {
            name "rgb_camera"
            fieldOfView 1.047
            width 640
            height 480
            far 20
          }
        ]
        name "camera_mount"
      }
    }
  ]
}
