#VRML_SIM R2025a utf8

EXTERNPROTO "https://raw.githubusercontent.com/cyberbotics/webots/R2025a/projects/objects/backgrounds/protos/TexturedBackground.proto"
EXTERNPROTO "https://raw.githubusercontent.com/cyberbotics/webots/R2025a/projects/objects/backgrounds/protos/TexturedBackgroundLight.proto"
EXTERNPROTO "https://raw.githubusercontent.com/cyberbotics/webots/R2025a/projects/robots/robotis/turtlebot/protos/TurtleBot3Burger.proto"
EXTERNPROTO "https://raw.githubusercontent.com/cyberbotics/webots/R2025a/projects/objects/solids/protos/SolidBox.proto"
EXTERNPROTO "https://raw.githubusercontent.com/cyberbotics/webots/R2025a/projects/devices/robotis/protos/RobotisLds01.proto"

WorldInfo {
}
Viewpoint {
  orientation -0.5773502691896258 0.5773502691896258 0.5773502691896258 2.0944
  position 2.0402902747584333e-05 2.040296043919825e-05 16.56742941166502
}
TexturedBackground {
}
TexturedBackgroundLight {
}
DEF FLOOR Solid {
  children [
    DEF FLOOR_SHAPE Shape {
      appearance PBRAppearance {
        baseColor 0.42 0.73 0.44
        roughness 1
        metalness 0
      }
      geometry Plane {
        size 4.2 4.2
      }
    }
  ]
  name "ground"
  boundingObject USE FLOOR_SHAPE
  locked TRUE
}
DEF FLOOR_BORDER Solid {
  translation 0 0 -0.001
  children [
    DEF FLOOR_BORDER_SHAPE Shape {
      appearance PBRAppearance {
        baseColor 0.21 0.22 0.24
        roughness 1
        metalness 0
      }
      geometry Plane {
        size 5.4 5.4
      }
    }
  ]
}
DEF WALL Solid {
  children [
    Shape {
      appearance DEF WALL_APPEARANCE PBRAppearance {
        baseColor 0.42 0.73 0.44
        roughness 1
        metalness 0
      }
      geometry DEF WALL_GEOMETRY IndexedFaceSet {
        coord Coordinate {
          point [
            -2.7 -2.7 0
            2.7 -2.7 0
            2.7 2.7 0
            -2.7 2.7 0
            -2.7 2.67 0
            2.67 2.67 0
            2.67 -2.67 0
            -2.67 -2.67 0
            -2.67 2.67 0
            -2.7 2.67 0
            -2.7 -2.7 0
            -2.7 -2.7 0.3
            2.7 -2.7 0.3
            2.7 2.7 0.3
            -2.7 2.7 0.3
            -2.7 2.67 0.3
            2.67 2.67 0.3
            2.67 -2.67 0.3
            -2.67 -2.67 0.3
            -2.67 2.67 0.3
            -2.7 2.67 0.3
            -2.7 -2.7 0.3
          ]
        }
        coordIndex [
          10, 9, 8, 7, 6, 5, 4, 3, 2, 1, 0, -1, 11, 12, 13, 14, 15, 16, 17, 18, 19, 20, 21, -1, 0, 1, 12, 11, -1, 1, 2, 13, 12, -1, 2, 3, 14, 13, -1, 3, 4, 15, 14, -1, 4, 5, 16, 15, -1, 5, 6, 17, 16, -1, 6, 7, 18, 17, -1, 7, 8, 19, 18, -1, 8, 9, 20, 19, -1, 9, 10, 21, 20, -1
        ]
      }
    }
  ]
  name "wall"
  boundingObject Group {
    children [
      Pose {
        translation 0 -2.67 0.15
        children [
          DEF WALL_SHAPE Shape {
            appearance USE WALL_APPEARANCE
            geometry Box {
              size 5.4 0.01 0.3
            }
          }
        ]
      }
      Pose {
        translation 0 2.67 0.15
        children [
          USE WALL_SHAPE
        ]
      }
      Pose {
        translation -2.67 0 0.15
        rotation 0 0 1 1.57
        children [
          USE WALL_SHAPE
        ]
      }
      Pose {
        translation 2.67 0 0.15
        rotation 0 0 1 1.57
        children [
          USE WALL_SHAPE
        ]
      }
    ]
  }
  locked TRUE
}
SolidBox {
  translation 0.5 1 0.1
  rotation 0 0 1 1.5708
  name "box(1)"
  size 0.2 0.2 0.2
  appearance PBRAppearance {
    baseColor 1 0 0
    roughness 1
    metalness 0
  }
}
SolidBox {
  translation 1.37 -0.99 0.1
  rotation 0 0 1 1.5708
  name "box(3)"
  size 0.2 0.2 0.2
  appearance PBRAppearance {
    baseColor 1 0 0
    roughness 1
    metalness 0
  }
}
TurtleBot3Burger {
  hidden position_0_1 -1.5932118316941947e-11
  hidden position_0_2 1.1371780577363995e-11
  hidden position_0_3 1.0373389112048882e-06
  hidden position2_0_3 0.00021830908416879316
  hidden position3_0_3 -3.274333090501158e-07
  hidden linearVelocity_0 -1.803333763338164e-16 -5.392717672094234e-16 2.9693049895783076e-16
  hidden angularVelocity_0 5.329914727358991e-15 -3.614482052815394e-15 1.1879410571128374e-16
  hidden rotation_12 0 1 0 5.077626172091576
  hidden linearVelocity_12 -1.070604823130263e-16 -1.9738127886807486e-16 8.726136293774888e-16
  hidden angularVelocity_12 -1.2471891883589282e-14 -2.8839696155788502e-15 1.0701744380397528e-16
  hidden rotation_13 -0.8084144965710665 3.616432125793182e-07 -0.5886136268670804 3.1415880565521914
  hidden linearVelocity_13 -1.0803553810264841e-16 -5.233935944691809e-16 1.246632320673485e-16
  hidden angularVelocity_13 5.350207808203759e-15 -3.290495582682815e-15 1.5172496293417588e-16
  hidden rotation_14 0.12319967320271884 -0.23361894479747775 0.9644915910231961 0.9078548354095707
  hidden linearVelocity_14 -7.320529963221948e-17 -3.293466776523381e-16 -5.55458198764706e-14
  hidden angularVelocity_14 8.233666665395634e-14 -1.8301324294771603e-14 -2.5729457441126284e-30
  translation 4.940038170198058e-10 -5.198628960309277e-10 -0.00024773920586920045
  rotation -0.0021129810645231038 -0.9999977676417208 4.75349366462757e-06 0.0046419467947908825
  controller "main_controller"
  extensionSlot [
    RobotisLds01 {
    }
    Display {
      width 150
      height 150
    }
    InertialUnit {
    }
    HingeJoint {
      jointParameters HingeJointParameters {
        position 62.868479999995216
        axis 0 0 1
        anchor 0 0 0.18
      }
      device [
        RotationalMotor {
          name "camera_motor"
        }
        PositionSensor {
          name "camera_motor_sensor"
        }
      ]
      endPoint Solid {
        translation 0 0 0.18
        rotation -0.04729851370347764 -0.7755888055023705 0.6294639428758791 6.090023258958706
        children [
          Camera {
            name "rgb_camera"
            fieldOfView 1.047
            width 640
            height 480
            far 20
          }
        ]
        name "camera_mount"
      }
    }
  ]
}
